<?xml version="1.0" ?>
<!-- =================================================================================== -->
<!-- |    This document was autogenerated by xacro from soft_hand_adaptive.urdf.xacro  | -->
<!-- |    EDITING THIS FILE BY HAND IS NOT RECOMMENDED                                 | -->
<!-- =================================================================================== -->
<robot name="soft_hand" xmlns:xacro="http://www.ros.org/wiki/xacro">
  <!-- include other model components -->
  <material name="SoftHand/LightGrey">
    <color rgba="0.7 0.7 0.7 1.0"/>
  </material>
  <material name="SoftHand/DarkGrey">
    <color rgba="0.4 0.4 0.4 1.0"/>
  </material>
  <material name="SoftHand/Black">
    <color rgba="0.0 0.0 0.0 1.0"/>
  </material>
  <material name="SoftHand/DarkGolden">
    <color rgba="0.4 0.4 0.3 1.0"/>
  </material>
  <material name="SoftHand/Blue">
    <color rgba="0.0 0.0 0.8 0.9"/>
  </material>
  <material name="SoftHand/LightBlue">
    <color rgba="0.0 0.4 1.0 0.5"/>
  </material>
  <!-- configure how all joints will behave in gazebo (particular behavior can be set at each joint as well) -->
  <!-- NOTE: inertia values are approximated using meshlab and only using the significant elements -->
  <!-- from http://answers.ros.org/question/11350/is-there-any-way-to-calculate-inertial-property-of-a-robot-to-simulate-it-in-gazebo/s
    One general rule of thumb I use for checking my inertia tensors is: If total mass of the rigid body is m, and the dimension of the corresponding body is d, then check to see if ixx, iyy, izz are near m*(d/2)^2.

    This is by no means correct, but a sanity check to make sure the moment of inertia are the right order of magnitudes, so the model behaves somewhat physically realistically.
    -->
  <!-- conversions -->
  <!-- I couldn't make the simulation work with realistic values, so I tweaked the conversion values -->
  <!-- not so negligible, otherwise simulation fails -->
  <!-- MESHLAB RESULT 
Opened mesh /home/crosales/Code/catkin_ws/src/pisa-iit-soft-hand/soft_hand/soft_hand_description/meshes/knuckle.stl in 9 msec
All files opened in 1398 msec
Enabled Decorate mode Show Axis
Mesh Bounding Box Size 34.382004 14.000006 24.628571
Mesh Bounding Box Diag 44.549847 
Mesh Volume is 3450.446777
Mesh Surface is 4583.448730
Thin shell barycenter 1.201245 0.001308 0.586193
Center of Mass is 1.285644 -0.000958 0.425011
Inertia Tensor is :
| 160373.578125 -18.966606 13918.184570 |
| -18.966606 311858.187500 59.538574 |
| 13918.184570 59.538574 249686.000000 |
Principal axes are :
| 0.988611 -0.000038 0.150492 |
| 0.000180 1.000000 -0.000933 |
| -0.150492 0.000949 0.988611 |
axis momenta are :
| 158254.859375 311858.250000 251804.656250 |
-->
  <!-- MESHLAB RESULT 
Opened mesh /home/crosales/Code/catkin_ws/src/pisa-iit-soft-hand/soft_hand/soft_hand_description/meshes/thumb_knuckle.stl in 6 msec
All files opened in 1493 msec
Enabled Decorate mode Show Axis
Mesh Bounding Box Size 38.298431 21.449932 21.967697
Mesh Bounding Box Diag 49.086140 
Mesh Volume is 3444.315186
Mesh Surface is 4292.456543
Thin shell barycenter 14.662230 -0.440256 0.060471
Center of Mass is 13.608098 -0.532174 -0.216691
Inertia Tensor is :
| 121779.453125 -25104.320312 -7351.798340 |
| -25104.320312 336414.968750 4401.581055 |
| -7351.798340 4401.581055 333794.062500 |
Principal axes are :
| 0.992996 -0.113512 0.032781 |
| 0.113844 0.845023 -0.522470 |
| 0.031606 0.522542 0.852027 |
axis momenta are :
| 118667.312500 342509.062500 330812.125000 |
-->
  <!-- MESHLAB RESULT 
Opened mesh /home/crosales/Code/catkin_ws/src/pisa-iit-soft-hand/soft_hand/soft_hand_description/meshes/phalanx.stl in 8 msec
All files opened in 1240 msec
Mesh Bounding Box Size 25.158094 14.000006 18.515181
Mesh Bounding Box Diag 34.230713 
Mesh Volume is 2003.388916
Mesh Surface is 2495.472412
Thin shell barycenter 5.001481 0.001261 0.002639
Center of Mass is 5.074337 -0.004524 -0.262953
Inertia Tensor is :
| 79493.273438 -2.796152 -5974.423340 |
| -2.796152 121398.460938 16.481358 |
| -5974.423340 16.481358 122965.343750 |
Principal axes are :
| 0.991019 0.000928 -0.133714 |
| 0.000013 0.999975 0.007040 |
| 0.133718 -0.006979 0.990995 |
axis momenta are :
| 78687.148438 121398.343750 123771.585938 |
-->
  <!-- MESHLAB RESULT 
Opened mesh /home/crosales/Code/catkin_ws/src/pisa-iit-soft-hand/soft_hand/soft_hand_description/meshes/fingertip.stl in 7 msec
All files opened in 1241 msec
Mesh Bounding Box Size 32.299561 14.000006 19.228573
Mesh Bounding Box Diag 40.112339 
Mesh Volume is 3519.114502
Mesh Surface is 4175.043945
Thin shell barycenter 8.126755 0.000146 0.955067
Center of Mass is 9.849094 0.000560 0.820286
Inertia Tensor is :
| 133971.296875 -13.962580 -14369.020508 |
| -13.962580 308096.281250 -12.146572 |
| -14369.020508 -12.146572 287758.875000 |
Principal axes are :
| 0.995737 -0.000033 -0.092238 |
| 0.000086 1.000000 0.000569 |
| 0.092238 -0.000574 0.995737 |
axis momenta are :
| 132640.250000 308096.281250 289089.906250 |
-->
  <!-- MESHLAB RESULT 
Opened mesh /home/crosales/Code/catkin_ws/src/pisa-iit-soft-hand/soft_hand/soft_hand_description/meshes/palm_right.stl in 13 msec
All files opened in 1178 msec
Mesh Bounding Box Size 36.539444 91.129791 84.829025
Mesh Bounding Box Diag 129.752579 
Mesh Volume is 76748.765625
Mesh Surface is 52111.375000
Thin shell barycenter -5.584415 -7.926011 28.832655
Center of Mass is -4.568758 -6.808116 27.653328
Inertia Tensor is :
| 55001040.000000 -714369.625000 -867280.437500 |
| -714369.625000 31722332.000000 -1570798.250000 |
| -867280.437500 -1570798.250000 37379544.000000 |
Principal axes are :
| 0.998540 0.038402 0.037998 |
| -0.027432 0.966351 -0.255759 |
| -0.046541 0.254343 0.965993 |
axis momenta are :
| 55061088.000000 31280510.000000 37761316.000000 |
-->
  <!-- accesories -->
  <!-- joint properties -->
  <!-- synergy vector -->
  <!-- synergy joint properties -->
  <!-- SOFT FINGER model -->
  <!-- 4 fingers are equal (index, middle, ring, little) -->
  <!-- THUMB MODEL -->
  <!-- It has one joint less than rest of fingers -->
  <!-- SOFT HAND MODEL -->
 
  <!-- PACMAN VERION ALREADY INCLUDES THE COUPLER, CLAMP AND BASE -->
  <!-- KUKA_COUPLER -->
  <link name="world">
    <visual>
      <origin rpy="0 0 0" xyz="0 0 0.0115"/>
      <geometry>
        <!-- mesh filename="package://soft_hand_description/meshes/accesories/kuka_coupler.stl"/-->
        <cylinder length="0.023" radius="0.033"/>
      </geometry>
      <material name="SoftHand/Blue"/>
    </visual>
    <collision>
      <origin rpy="0 0 0" xyz="0 0 0.031"/>
      <geometry>
        <cylinder length="0.023" radius="0.033"/>
      </geometry>
    </collision>
  </link>
  <joint name="box_soft_hand_kuka_coupler_base_joint" type="fixed">
    <origin rpy="0 0 0" xyz="0 0 0.023"/>
    <parent link="world"/>
    <child link="soft_hand_kuka_coupler"/>
  </joint>
  <link name="soft_hand_kuka_coupler"/>
  <!-- CLAMP -->
  <joint name="soft_hand_kuka_coupler_soft_hand_clamp_joint" type="fixed">
    <origin rpy="0 0 0" xyz="0 0 0.01"/>
    <parent link="soft_hand_kuka_coupler"/>
    <child link="soft_hand_clamp"/>
  </joint>
  <link name="soft_hand_clamp">
    <visual>
      <origin rpy="0 0 0" xyz="0 0 0"/>
      <geometry>
        <mesh filename="package://soft_hand_description/meshes/accesories/clamp.stl"/>
      </geometry>
      <material name="SoftHand/Blue"/>
    </visual>
    <collision>
      <origin rpy="0 0 0" xyz="0 0 0"/>
      <geometry>
        <box size="0.066 0.0725 0.0256"/>
      </geometry>
    </collision>
  </link>
  <!-- SOFT HAND BASE -->
  <joint name="soft_hand_clamp_soft_hand_softhand_base_joint" type="fixed">
    <origin rpy="0 0 0" xyz="0 0 0.004"/>
    <parent link="soft_hand_clamp"/>
    <child link="soft_hand_softhand_base"/>
  </joint>
  <link name="soft_hand_softhand_base">
    <visual>
      <origin rpy="0 0 0" xyz="0 0 0"/>
      <geometry>
        <mesh filename="package://soft_hand_description/meshes/accesories/softhand_base_right.stl"/>
      </geometry>
      <material name="SoftHand/Blue"/>
    </visual>
    <collision>
      <origin rpy="0 0 0" xyz="0 0 0.031"/>
      <geometry>
        <box size="0.066 0.066 0.062"/>
      </geometry>
    </collision>
  </link>
  <!-- PALM -->
  <joint name="soft_hand_palm_joint" type="fixed">
    <origin rpy="0 0 0" xyz="0.002 0.00695 0.0535"/>
    <parent link="soft_hand_softhand_base"/>
    <child link="soft_hand_palm_link"/>
  </joint>
  <link name="soft_hand_palm_link">
    <inertial>
      <origin xyz="-0.004568758 -0.006808116 0.027653328"/>
      <mass value="2.28"/>
      <inertia ixx="1.6302" ixy="0.0228" ixz="0.0228" iyy="0.9462" iyz="0.0456" izz="1.1058"/>
    </inertial>
    <visual>
      <geometry>
        <mesh filename="package://soft_hand_description/meshes/palm_right.stl" scale=" .001 .001 .001"/>
      </geometry>
      <material name="SoftHand/DarkGrey"/>
    </visual>
    <collision>
      <geometry>
        <mesh filename="package://soft_hand_description/meshes/palm_right_collision.stl" scale=" .001 .001 .001"/>
      </geometry>
    </collision>
  </link>
  <!-- MOTOR JOINT -->
  <joint name="soft_hand_synergy_joint" type="revolute">
    <parent link="soft_hand_palm_link"/>
    <child link="soft_hand_invisible_wire_link"/>
    <axis xyz="0 0 1"/>
    <limit effort="100" lower="0.0" upper="1.0" velocity="100000"/>
    <dynamics damping="0.5" friction="0.0"/>
  </joint>
  <link name="soft_hand_invisible_wire_link">
    <inertial>
      <origin xyz="0 0 0"/>
      <mass value="0.1"/>
      <inertia ixx="0.001" ixy="0.0" ixz="0.0" iyy="0.001" iyz="0.0" izz="0.001"/>
    </inertial>
  </link>
  <!-- THUMB AND FINGERS -->
  <!-- change anchor points accordingly to the leftness -->
  <!-- KNUCKLE -->
  <joint name="soft_hand_thumb_abd_joint" type="revolute">
    <origin rpy="0.0 -0.38397275793662144 1.5707963267948966" xyz="0.00566972 0.0296160 0.0553140"/>
    <parent link="soft_hand_palm_link"/>
    <child link="soft_hand_thumb_knuckle_link"/>
    <axis xyz="0 0 -1"/>
    <limit effort="100" lower="0.0" upper="1.57079632679" velocity="100"/>
    <dynamics damping="0.5" friction="0.0"/>
  </joint>
  <link name="soft_hand_thumb_knuckle_link">
    <inertial>
      <origin xyz="0.013608098 -0.000532174 -0.000216691"/>
      <mass value="0.09"/>
      <inertia ixx="0.00315" ixy="0.00027" ixz="-0.00054" iyy="0.009" iyz="0.00018" izz="0.009"/>
    </inertial>
    <visual>
      <geometry>
        <mesh filename="package://soft_hand_description/meshes/thumb_knuckle_right.stl" scale=" .001 .001 .001"/>
      </geometry>
      <material name="SoftHand/DarkGrey"/>
    </visual>
    <collision>
      <geometry>
        <mesh filename="package://soft_hand_description/meshes/thumb_knuckle_right_collision.stl" scale=" .001 .001 .001"/>
      </geometry>
    </collision>
  </link>
  <!-- PROXIMAL PHALANGE -->
  <joint name="soft_hand_thumb_inner_joint" type="revolute">
    <!-- <origin xyz="0.022500000 -0.003300000 0.0" rpy="0.42662757656587236 0.0 0.18131960430075023" /> -->
    <origin rpy="0.42662757656587236 0.0 0.0" xyz="0.022500000 -0.003300000 0.0"/>
    <parent link="soft_hand_thumb_knuckle_link"/>
    <child link="soft_hand_thumb_fake_link1"/>
    <axis xyz="0 -1 0"/>
    <limit effort="100" lower="0.0" upper="0.785398163397" velocity="100"/>
    <dynamics damping="0.5" friction="0.0"/>
  </joint>
  <link name="soft_hand_thumb_fake_link1">
    <inertial>
      <origin xyz="0 0 0"/>
      <mass value="0.1"/>
      <inertia ixx="0.001" ixy="0.0" ixz="0.0" iyy="0.001" iyz="0.0" izz="0.001"/>
    </inertial>
  </link>
  <joint name="soft_hand_thumb_inner_joint_mimic" type="revolute">
    <origin rpy="0 0 0" xyz="0.013 0 0"/>
    <parent link="soft_hand_thumb_fake_link1"/>
    <child link="soft_hand_thumb_proximal_link"/>
    <axis xyz="0 -1 0"/>
    <limit effort="100" lower="0.0" upper="0.785398163397" velocity="100"/>
    <dynamics damping="0.5" friction="0.0"/>
  </joint>
  <link name="soft_hand_thumb_proximal_link">
    <inertial>
      <origin xyz="0.005074337 -4.524e-06 -0.000262953"/>
      <mass value="0.05"/>
      <inertia ixx="0.00175" ixy="0.0" ixz="0.0001" iyy="0.00275" iyz="0.0" izz="0.00275"/>
    </inertial>
    <visual>
      <geometry>
        <mesh filename="package://soft_hand_description/meshes/phalanx.stl" scale=" .001 .001 .001"/>
      </geometry>
      <material name="SoftHand/DarkGrey"/>
    </visual>
    <collision>
      <geometry>
        <mesh filename="package://soft_hand_description/meshes/phalanx_collision.stl" scale=" .001 .001 .001"/>
      </geometry>
    </collision>
  </link>
  <!-- DISTAL PHALANGE -->
  <joint name="soft_hand_thumb_outer_joint" type="revolute">
    <origin rpy="0 0 0" xyz="0.009 0 0.0"/>
    <parent link="soft_hand_thumb_proximal_link"/>
    <child link="soft_hand_thumb_fake_link3"/>
    <axis xyz="0 -1 0"/>
    <limit effort="100" lower="0.0" upper="0.785398163397" velocity="100"/>
    <dynamics damping="0.5" friction="0.0"/>
  </joint>
  <link name="soft_hand_thumb_fake_link3">
    <inertial>
      <origin xyz="0 0 0"/>
      <mass value="0.1"/>
      <inertia ixx="0.001" ixy="0.0" ixz="0.0" iyy="0.001" iyz="0.0" izz="0.001"/>
    </inertial>
  </link>
  <joint name="soft_hand_thumb_outer_joint_mimic" type="revolute">
    <origin rpy="0 0 0" xyz="0.013 0 0"/>
    <parent link="soft_hand_thumb_fake_link3"/>
    <child link="soft_hand_thumb_distal_link"/>
    <axis xyz="0 -1 0"/>
    <limit effort="100" lower="0.0" upper="0.785398163397" velocity="100"/>
    <dynamics damping="0.5" friction="0.0"/>
  </joint>
  <link name="soft_hand_thumb_distal_link">
    <inertial>
      <origin xyz="0.009849094 5.6e-07 0.000820286"/>
      <mass value="0.1"/>
      <inertia ixx="0.0035" ixy="0.0" ixz="0.0002" iyy="0.008" iyz="0.0" izz="0.0076"/>
    </inertial>
    <visual>
      <geometry>
        <mesh filename="package://soft_hand_description/meshes/fingertip.stl" scale=" .001 .001 .001"/>
      </geometry>
      <material name="SoftHand/DarkGrey"/>
    </visual>
    <collision>
      <geometry>
        <mesh filename="package://soft_hand_description/meshes/fingertip_collision.stl" scale=" .001 .001 .001"/>
      </geometry>
    </collision>
  </link>
  <!-- KNUCKLE -->
  <joint name="soft_hand_index_abd_joint" type="revolute">
    <origin rpy="1.5707963267948966 -1.4835299330931884 1.5707963267948966" xyz="-0.0033 0.0195 0.0936994"/>
    <parent link="soft_hand_palm_link"/>
    <child link="soft_hand_index_knuckle_link"/>
    <axis xyz="0 0 1"/>
    <limit effort="100" lower="-0.523598775598" upper="0.523598775598" velocity="100"/>
    <dynamics damping="0.5" friction="0.0"/>
  </joint>
  <link name="soft_hand_index_knuckle_link">
    <inertial>
      <origin xyz="0.001285644 -9.58e-07 0.000425011"/>
      <mass value="0.09"/>
      <inertia ixx="0.00405" ixy="0.0" ixz="0.00045" iyy="0.0081" iyz="0.0" izz="0.0063"/>
    </inertial>
    <visual>
      <geometry>
        <mesh filename="package://soft_hand_description/meshes/knuckle.stl" scale=" .001 .001 .001"/>
      </geometry>
      <material name="SoftHand/DarkGrey"/>
    </visual>
    <collision>
      <geometry>
        <mesh filename="package://soft_hand_description/meshes/knuckle_collision.stl" scale=" .001 .001 .001"/>
      </geometry>
    </collision>
  </link>
  <!-- PROXIMAL PHALANGE -->
  <joint name="soft_hand_index_inner_joint" type="revolute">
    <origin rpy="0 0 0" xyz="0.009 0 0"/>
    <parent link="soft_hand_index_knuckle_link"/>
    <child link="soft_hand_index_fake_link1"/>
    <axis xyz="0 -1 0"/>
    <limit effort="100" lower="0.0" upper="0.785398163397" velocity="100"/>
    <dynamics damping="0.5" friction="0.0"/>
  </joint>
  <link name="soft_hand_index_fake_link1">
    <inertial>
      <origin xyz="0 0 0"/>
      <mass value="0.1"/>
      <inertia ixx="0.001" ixy="0.0" ixz="0.0" iyy="0.001" iyz="0.0" izz="0.001"/>
    </inertial>
  </link>
  <joint name="soft_hand_index_inner_joint_mimic" type="revolute">
    <origin rpy="0 0 0" xyz="0.013 0 0"/>
    <parent link="soft_hand_index_fake_link1"/>
    <child link="soft_hand_index_proximal_link"/>
    <axis xyz="0 -1 0"/>
    <limit effort="100" lower="0.0" upper="0.785398163397" velocity="100"/>
    <dynamics damping="0.5" friction="0.0"/>
  </joint>
  <link name="soft_hand_index_proximal_link">
    <inertial>
      <origin xyz="0.005074337 -4.524e-06 -0.000262953"/>
      <mass value="0.05"/>
      <inertia ixx="0.00175" ixy="0.0" ixz="0.0001" iyy="0.00275" iyz="0.0" izz="0.00275"/>
    </inertial>
    <visual>
      <geometry>
        <mesh filename="package://soft_hand_description/meshes/phalanx.stl" scale=" .001 .001 .001"/>
      </geometry>
      <material name="SoftHand/DarkGrey"/>
    </visual>
    <collision>
      <geometry>
        <mesh filename="package://soft_hand_description/meshes/phalanx_collision.stl" scale=" .001 .001 .001"/>
      </geometry>
    </collision>
  </link>
  <!-- MIDDLE PHALANGE -->
  <joint name="soft_hand_index_middle_joint" type="revolute">
    <origin rpy="0 0 0" xyz="0.009 0 0"/>
    <parent link="soft_hand_index_proximal_link"/>
    <child link="soft_hand_index_fake_link2"/>
    <axis xyz="0 -1 0"/>
    <limit effort="100" lower="0.0" upper="0.785398163397" velocity="100"/>
    <dynamics damping="0.5" friction="0.0"/>
  </joint>
  <link name="soft_hand_index_fake_link2">
    <inertial>
      <origin xyz="0 0 0"/>
      <mass value="0.1"/>
      <inertia ixx="0.001" ixy="0.0" ixz="0.0" iyy="0.001" iyz="0.0" izz="0.001"/>
    </inertial>
  </link>
  <joint name="soft_hand_index_middle_joint_mimic" type="revolute">
    <origin rpy="0 0 0" xyz="0.013 0 0"/>
    <parent link="soft_hand_index_fake_link2"/>
    <child link="soft_hand_index_middle_link"/>
    <axis xyz="0 -1 0"/>
    <limit effort="100" lower="0.0" upper="0.785398163397" velocity="100"/>
    <dynamics damping="0.5" friction="0.0"/>
  </joint>
  <link name="soft_hand_index_middle_link">
    <inertial>
      <origin xyz="0.005074337 -4.524e-06 -0.000262953"/>
      <mass value="0.05"/>
      <inertia ixx="0.00175" ixy="0.0" ixz="0.0001" iyy="0.00275" iyz="0.0" izz="0.00275"/>
    </inertial>
    <visual>
      <geometry>
        <mesh filename="package://soft_hand_description/meshes/phalanx.stl" scale=" .001 .001 .001"/>
      </geometry>
      <material name="SoftHand/DarkGrey"/>
    </visual>
    <collision>
      <geometry>
        <mesh filename="package://soft_hand_description/meshes/phalanx_collision.stl" scale=" .001 .001 .001"/>
      </geometry>
    </collision>
  </link>
  <!-- DISTAL PHALANGE -->
  <joint name="soft_hand_index_outer_joint" type="revolute">
    <origin rpy="0 0 0" xyz="0.009 0 0"/>
    <parent link="soft_hand_index_middle_link"/>
    <child link="soft_hand_index_fake_link3"/>
    <axis xyz="0 -1 0"/>
    <limit effort="100" lower="0.0" upper="0.785398163397" velocity="100"/>
    <dynamics damping="0.5" friction="0.0"/>
  </joint>
  <link name="soft_hand_index_fake_link3">
    <inertial>
      <origin xyz="0 0 0"/>
      <mass value="0.1"/>
      <inertia ixx="0.001" ixy="0.0" ixz="0.0" iyy="0.001" iyz="0.0" izz="0.001"/>
    </inertial>
  </link>
  <joint name="soft_hand_index_outer_joint_mimic" type="revolute">
    <origin rpy="0 0 0" xyz="0.013 0 0"/>
    <parent link="soft_hand_index_fake_link3"/>
    <child link="soft_hand_index_distal_link"/>
    <axis xyz="0 -1 0"/>
    <limit effort="100" lower="0.0" upper="0.785398163397" velocity="100"/>
    <dynamics damping="0.5" friction="0.0"/>
  </joint>
  <link name="soft_hand_index_distal_link">
    <inertial>
      <origin xyz="0.009849094 5.6e-07 0.000820286"/>
      <mass value="0.1"/>
      <inertia ixx="0.0035" ixy="0.0" ixz="0.0002" iyy="0.008" iyz="0.0" izz="0.0076"/>
    </inertial>
    <visual>
      <geometry>
        <mesh filename="package://soft_hand_description/meshes/fingertip.stl" scale=" .001 .001 .001"/>
      </geometry>
      <material name="SoftHand/DarkGrey"/>
    </visual>
    <collision>
      <geometry>
        <mesh filename="package://soft_hand_description/meshes/fingertip_collision.stl" scale=" .001 .001 .001"/>
      </geometry>
    </collision>
  </link>
  <!-- KNUCKLE -->
  <joint name="soft_hand_middle_abd_joint" type="revolute">
    <origin rpy="3.141592 -1.5707963267948966 0.0" xyz="-0.003300000 0.0 0.100699"/>
    <parent link="soft_hand_palm_link"/>
    <child link="soft_hand_middle_knuckle_link"/>
    <axis xyz="0 0 1"/>
    <limit effort="100" lower="-0.523598775598" upper="0.523598775598" velocity="100"/>
    <dynamics damping="0.5" friction="0.0"/>
  </joint>
  <link name="soft_hand_middle_knuckle_link">
    <inertial>
      <origin xyz="0.001285644 -9.58e-07 0.000425011"/>
      <mass value="0.09"/>
      <inertia ixx="0.00405" ixy="0.0" ixz="0.00045" iyy="0.0081" iyz="0.0" izz="0.0063"/>
    </inertial>
    <visual>
      <geometry>
        <mesh filename="package://soft_hand_description/meshes/knuckle.stl" scale=" .001 .001 .001"/>
      </geometry>
      <material name="SoftHand/DarkGrey"/>
    </visual>
    <collision>
      <geometry>
        <mesh filename="package://soft_hand_description/meshes/knuckle_collision.stl" scale=" .001 .001 .001"/>
      </geometry>
    </collision>
  </link>
  <!-- PROXIMAL PHALANGE -->
  <joint name="soft_hand_middle_inner_joint" type="revolute">
    <origin rpy="0 0 0" xyz="0.009 0 0"/>
    <parent link="soft_hand_middle_knuckle_link"/>
    <child link="soft_hand_middle_fake_link1"/>
    <axis xyz="0 -1 0"/>
    <limit effort="100" lower="0.0" upper="0.785398163397" velocity="100"/>
    <dynamics damping="0.5" friction="0.0"/>
  </joint>
  <link name="soft_hand_middle_fake_link1">
    <inertial>
      <origin xyz="0 0 0"/>
      <mass value="0.1"/>
      <inertia ixx="0.001" ixy="0.0" ixz="0.0" iyy="0.001" iyz="0.0" izz="0.001"/>
    </inertial>
  </link>
  <joint name="soft_hand_middle_inner_joint_mimic" type="revolute">
    <origin rpy="0 0 0" xyz="0.013 0 0"/>
    <parent link="soft_hand_middle_fake_link1"/>
    <child link="soft_hand_middle_proximal_link"/>
    <axis xyz="0 -1 0"/>
    <limit effort="100" lower="0.0" upper="0.785398163397" velocity="100"/>
    <dynamics damping="0.5" friction="0.0"/>
  </joint>
  <link name="soft_hand_middle_proximal_link">
    <inertial>
      <origin xyz="0.005074337 -4.524e-06 -0.000262953"/>
      <mass value="0.05"/>
      <inertia ixx="0.00175" ixy="0.0" ixz="0.0001" iyy="0.00275" iyz="0.0" izz="0.00275"/>
    </inertial>
    <visual>
      <geometry>
        <mesh filename="package://soft_hand_description/meshes/phalanx.stl" scale=" .001 .001 .001"/>
      </geometry>
      <material name="SoftHand/DarkGrey"/>
    </visual>
    <collision>
      <geometry>
        <mesh filename="package://soft_hand_description/meshes/phalanx_collision.stl" scale=" .001 .001 .001"/>
      </geometry>
    </collision>
  </link>
  <!-- MIDDLE PHALANGE -->
  <joint name="soft_hand_middle_middle_joint" type="revolute">
    <origin rpy="0 0 0" xyz="0.009 0 0"/>
    <parent link="soft_hand_middle_proximal_link"/>
    <child link="soft_hand_middle_fake_link2"/>
    <axis xyz="0 -1 0"/>
    <limit effort="100" lower="0.0" upper="0.785398163397" velocity="100"/>
    <dynamics damping="0.5" friction="0.0"/>
  </joint>
  <link name="soft_hand_middle_fake_link2">
    <inertial>
      <origin xyz="0 0 0"/>
      <mass value="0.1"/>
      <inertia ixx="0.001" ixy="0.0" ixz="0.0" iyy="0.001" iyz="0.0" izz="0.001"/>
    </inertial>
  </link>
  <joint name="soft_hand_middle_middle_joint_mimic" type="revolute">
    <origin rpy="0 0 0" xyz="0.013 0 0"/>
    <parent link="soft_hand_middle_fake_link2"/>
    <child link="soft_hand_middle_middle_link"/>
    <axis xyz="0 -1 0"/>
    <limit effort="100" lower="0.0" upper="0.785398163397" velocity="100"/>
    <dynamics damping="0.5" friction="0.0"/>
  </joint>
  <link name="soft_hand_middle_middle_link">
    <inertial>
      <origin xyz="0.005074337 -4.524e-06 -0.000262953"/>
      <mass value="0.05"/>
      <inertia ixx="0.00175" ixy="0.0" ixz="0.0001" iyy="0.00275" iyz="0.0" izz="0.00275"/>
    </inertial>
    <visual>
      <geometry>
        <mesh filename="package://soft_hand_description/meshes/phalanx.stl" scale=" .001 .001 .001"/>
      </geometry>
      <material name="SoftHand/DarkGrey"/>
    </visual>
    <collision>
      <geometry>
        <mesh filename="package://soft_hand_description/meshes/phalanx_collision.stl" scale=" .001 .001 .001"/>
      </geometry>
    </collision>
  </link>
  <!-- DISTAL PHALANGE -->
  <joint name="soft_hand_middle_outer_joint" type="revolute">
    <origin rpy="0 0 0" xyz="0.009 0 0"/>
    <parent link="soft_hand_middle_middle_link"/>
    <child link="soft_hand_middle_fake_link3"/>
    <axis xyz="0 -1 0"/>
    <limit effort="100" lower="0.0" upper="0.785398163397" velocity="100"/>
    <dynamics damping="0.5" friction="0.0"/>
  </joint>
  <link name="soft_hand_middle_fake_link3">
    <inertial>
      <origin xyz="0 0 0"/>
      <mass value="0.1"/>
      <inertia ixx="0.001" ixy="0.0" ixz="0.0" iyy="0.001" iyz="0.0" izz="0.001"/>
    </inertial>
  </link>
  <joint name="soft_hand_middle_outer_joint_mimic" type="revolute">
    <origin rpy="0 0 0" xyz="0.013 0 0"/>
    <parent link="soft_hand_middle_fake_link3"/>
    <child link="soft_hand_middle_distal_link"/>
    <axis xyz="0 -1 0"/>
    <limit effort="100" lower="0.0" upper="0.785398163397" velocity="100"/>
    <dynamics damping="0.5" friction="0.0"/>
  </joint>
  <link name="soft_hand_middle_distal_link">
    <inertial>
      <origin xyz="0.009849094 5.6e-07 0.000820286"/>
      <mass value="0.1"/>
      <inertia ixx="0.0035" ixy="0.0" ixz="0.0002" iyy="0.008" iyz="0.0" izz="0.0076"/>
    </inertial>
    <visual>
      <geometry>
        <mesh filename="package://soft_hand_description/meshes/fingertip.stl" scale=" .001 .001 .001"/>
      </geometry>
      <material name="SoftHand/DarkGrey"/>
    </visual>
    <collision>
      <geometry>
        <mesh filename="package://soft_hand_description/meshes/fingertip_collision.stl" scale=" .001 .001 .001"/>
      </geometry>
    </collision>
  </link>
  <!-- KNUCKLE -->
  <joint name="soft_hand_ring_abd_joint" type="revolute">
    <origin rpy="-1.5707963267948966 -1.5184364298870514 -1.5707963267948966 " xyz="-0.0033 -0.0195 0.0936994"/>
    <parent link="soft_hand_palm_link"/>
    <child link="soft_hand_ring_knuckle_link"/>
    <axis xyz="0 0 1"/>
    <limit effort="100" lower="-0.523598775598" upper="0.523598775598" velocity="100"/>
    <dynamics damping="0.5" friction="0.0"/>
  </joint>
  <link name="soft_hand_ring_knuckle_link">
    <inertial>
      <origin xyz="0.001285644 -9.58e-07 0.000425011"/>
      <mass value="0.09"/>
      <inertia ixx="0.00405" ixy="0.0" ixz="0.00045" iyy="0.0081" iyz="0.0" izz="0.0063"/>
    </inertial>
    <visual>
      <geometry>
        <mesh filename="package://soft_hand_description/meshes/knuckle.stl" scale=" .001 .001 .001"/>
      </geometry>
      <material name="SoftHand/DarkGrey"/>
    </visual>
    <collision>
      <geometry>
        <mesh filename="package://soft_hand_description/meshes/knuckle_collision.stl" scale=" .001 .001 .001"/>
      </geometry>
    </collision>
  </link>
  <!-- PROXIMAL PHALANGE -->
  <joint name="soft_hand_ring_inner_joint" type="revolute">
    <origin rpy="0 0 0" xyz="0.009 0 0"/>
    <parent link="soft_hand_ring_knuckle_link"/>
    <child link="soft_hand_ring_fake_link1"/>
    <axis xyz="0 -1 0"/>
    <limit effort="100" lower="0.0" upper="0.785398163397" velocity="100"/>
    <dynamics damping="0.5" friction="0.0"/>
  </joint>
  <link name="soft_hand_ring_fake_link1">
    <inertial>
      <origin xyz="0 0 0"/>
      <mass value="0.1"/>
      <inertia ixx="0.001" ixy="0.0" ixz="0.0" iyy="0.001" iyz="0.0" izz="0.001"/>
    </inertial>
  </link>
  <joint name="soft_hand_ring_inner_joint_mimic" type="revolute">
    <origin rpy="0 0 0" xyz="0.013 0 0"/>
    <parent link="soft_hand_ring_fake_link1"/>
    <child link="soft_hand_ring_proximal_link"/>
    <axis xyz="0 -1 0"/>
    <limit effort="100" lower="0.0" upper="0.785398163397" velocity="100"/>
    <dynamics damping="0.5" friction="0.0"/>
  </joint>
  <link name="soft_hand_ring_proximal_link">
    <inertial>
      <origin xyz="0.005074337 -4.524e-06 -0.000262953"/>
      <mass value="0.05"/>
      <inertia ixx="0.00175" ixy="0.0" ixz="0.0001" iyy="0.00275" iyz="0.0" izz="0.00275"/>
    </inertial>
    <visual>
      <geometry>
        <mesh filename="package://soft_hand_description/meshes/phalanx.stl" scale=" .001 .001 .001"/>
      </geometry>
      <material name="SoftHand/DarkGrey"/>
    </visual>
    <collision>
      <geometry>
        <mesh filename="package://soft_hand_description/meshes/phalanx_collision.stl" scale=" .001 .001 .001"/>
      </geometry>
    </collision>
  </link>
  <!-- MIDDLE PHALANGE -->
  <joint name="soft_hand_ring_middle_joint" type="revolute">
    <origin rpy="0 0 0" xyz="0.009 0 0"/>
    <parent link="soft_hand_ring_proximal_link"/>
    <child link="soft_hand_ring_fake_link2"/>
    <axis xyz="0 -1 0"/>
    <limit effort="100" lower="0.0" upper="0.785398163397" velocity="100"/>
    <dynamics damping="0.5" friction="0.0"/>
  </joint>
  <link name="soft_hand_ring_fake_link2">
    <inertial>
      <origin xyz="0 0 0"/>
      <mass value="0.1"/>
      <inertia ixx="0.001" ixy="0.0" ixz="0.0" iyy="0.001" iyz="0.0" izz="0.001"/>
    </inertial>
  </link>
  <joint name="soft_hand_ring_middle_joint_mimic" type="revolute">
    <origin rpy="0 0 0" xyz="0.013 0 0"/>
    <parent link="soft_hand_ring_fake_link2"/>
    <child link="soft_hand_ring_middle_link"/>
    <axis xyz="0 -1 0"/>
    <limit effort="100" lower="0.0" upper="0.785398163397" velocity="100"/>
    <dynamics damping="0.5" friction="0.0"/>
  </joint>
  <link name="soft_hand_ring_middle_link">
    <inertial>
      <origin xyz="0.005074337 -4.524e-06 -0.000262953"/>
      <mass value="0.05"/>
      <inertia ixx="0.00175" ixy="0.0" ixz="0.0001" iyy="0.00275" iyz="0.0" izz="0.00275"/>
    </inertial>
    <visual>
      <geometry>
        <mesh filename="package://soft_hand_description/meshes/phalanx.stl" scale=" .001 .001 .001"/>
      </geometry>
      <material name="SoftHand/DarkGrey"/>
    </visual>
    <collision>
      <geometry>
        <mesh filename="package://soft_hand_description/meshes/phalanx_collision.stl" scale=" .001 .001 .001"/>
      </geometry>
    </collision>
  </link>
  <!-- DISTAL PHALANGE -->
  <joint name="soft_hand_ring_outer_joint" type="revolute">
    <origin rpy="0 0 0" xyz="0.009 0 0"/>
    <parent link="soft_hand_ring_middle_link"/>
    <child link="soft_hand_ring_fake_link3"/>
    <axis xyz="0 -1 0"/>
    <limit effort="100" lower="0.0" upper="0.785398163397" velocity="100"/>
    <dynamics damping="0.5" friction="0.0"/>
  </joint>
  <link name="soft_hand_ring_fake_link3">
    <inertial>
      <origin xyz="0 0 0"/>
      <mass value="0.1"/>
      <inertia ixx="0.001" ixy="0.0" ixz="0.0" iyy="0.001" iyz="0.0" izz="0.001"/>
    </inertial>
  </link>
  <joint name="soft_hand_ring_outer_joint_mimic" type="revolute">
    <origin rpy="0 0 0" xyz="0.013 0 0"/>
    <parent link="soft_hand_ring_fake_link3"/>
    <child link="soft_hand_ring_distal_link"/>
    <axis xyz="0 -1 0"/>
    <limit effort="100" lower="0.0" upper="0.785398163397" velocity="100"/>
    <dynamics damping="0.5" friction="0.0"/>
  </joint>
  <link name="soft_hand_ring_distal_link">
    <inertial>
      <origin xyz="0.009849094 5.6e-07 0.000820286"/>
      <mass value="0.1"/>
      <inertia ixx="0.0035" ixy="0.0" ixz="0.0002" iyy="0.008" iyz="0.0" izz="0.0076"/>
    </inertial>
    <visual>
      <geometry>
        <mesh filename="package://soft_hand_description/meshes/fingertip.stl" scale=" .001 .001 .001"/>
      </geometry>
      <material name="SoftHand/DarkGrey"/>
    </visual>
    <collision>
      <geometry>
        <mesh filename="package://soft_hand_description/meshes/fingertip_collision.stl" scale=" .001 .001 .001"/>
      </geometry>
    </collision>
  </link>
  <!-- KNUCKLE -->
  <joint name="soft_hand_little_abd_joint" type="revolute">
    <origin rpy="-1.5707963267948966 -1.4835299330931884 -1.5707963267948966" xyz="-0.0033 -0.039 0.0836994"/>
    <parent link="soft_hand_palm_link"/>
    <child link="soft_hand_little_knuckle_link"/>
    <axis xyz="0 0 1"/>
    <limit effort="100" lower="-0.523598775598" upper="0.523598775598" velocity="100"/>
    <dynamics damping="0.5" friction="0.0"/>
  </joint>
  <link name="soft_hand_little_knuckle_link">
    <inertial>
      <origin xyz="0.001285644 -9.58e-07 0.000425011"/>
      <mass value="0.09"/>
      <inertia ixx="0.00405" ixy="0.0" ixz="0.00045" iyy="0.0081" iyz="0.0" izz="0.0063"/>
    </inertial>
    <visual>
      <geometry>
        <mesh filename="package://soft_hand_description/meshes/knuckle.stl" scale=" .001 .001 .001"/>
      </geometry>
      <material name="SoftHand/DarkGrey"/>
    </visual>
    <collision>
      <geometry>
        <mesh filename="package://soft_hand_description/meshes/knuckle_collision.stl" scale=" .001 .001 .001"/>
      </geometry>
    </collision>
  </link>
  <!-- PROXIMAL PHALANGE -->
  <joint name="soft_hand_little_inner_joint" type="revolute">
    <origin rpy="0 0 0" xyz="0.009 0 0"/>
    <parent link="soft_hand_little_knuckle_link"/>
    <child link="soft_hand_little_fake_link1"/>
    <axis xyz="0 -1 0"/>
    <limit effort="100" lower="0.0" upper="0.785398163397" velocity="100"/>
    <dynamics damping="0.5" friction="0.0"/>
  </joint>
  <link name="soft_hand_little_fake_link1">
    <inertial>
      <origin xyz="0 0 0"/>
      <mass value="0.1"/>
      <inertia ixx="0.001" ixy="0.0" ixz="0.0" iyy="0.001" iyz="0.0" izz="0.001"/>
    </inertial>
  </link>
  <joint name="soft_hand_little_inner_joint_mimic" type="revolute">
    <origin rpy="0 0 0" xyz="0.013 0 0"/>
    <parent link="soft_hand_little_fake_link1"/>
    <child link="soft_hand_little_proximal_link"/>
    <axis xyz="0 -1 0"/>
    <limit effort="100" lower="0.0" upper="0.785398163397" velocity="100"/>
    <dynamics damping="0.5" friction="0.0"/>
  </joint>
  <link name="soft_hand_little_proximal_link">
    <inertial>
      <origin xyz="0.005074337 -4.524e-06 -0.000262953"/>
      <mass value="0.05"/>
      <inertia ixx="0.00175" ixy="0.0" ixz="0.0001" iyy="0.00275" iyz="0.0" izz="0.00275"/>
    </inertial>
    <visual>
      <geometry>
        <mesh filename="package://soft_hand_description/meshes/phalanx.stl" scale=" .001 .001 .001"/>
      </geometry>
      <material name="SoftHand/DarkGrey"/>
    </visual>
    <collision>
      <geometry>
        <mesh filename="package://soft_hand_description/meshes/phalanx_collision.stl" scale=" .001 .001 .001"/>
      </geometry>
    </collision>
  </link>
  <!-- MIDDLE PHALANGE -->
  <joint name="soft_hand_little_middle_joint" type="revolute">
    <origin rpy="0 0 0" xyz="0.009 0 0"/>
    <parent link="soft_hand_little_proximal_link"/>
    <child link="soft_hand_little_fake_link2"/>
    <axis xyz="0 -1 0"/>
    <limit effort="100" lower="0.0" upper="0.785398163397" velocity="100"/>
    <dynamics damping="0.5" friction="0.0"/>
  </joint>
  <link name="soft_hand_little_fake_link2">
    <inertial>
      <origin xyz="0 0 0"/>
      <mass value="0.1"/>
      <inertia ixx="0.001" ixy="0.0" ixz="0.0" iyy="0.001" iyz="0.0" izz="0.001"/>
    </inertial>
  </link>
  <joint name="soft_hand_little_middle_joint_mimic" type="revolute">
    <origin rpy="0 0 0" xyz="0.013 0 0"/>
    <parent link="soft_hand_little_fake_link2"/>
    <child link="soft_hand_little_middle_link"/>
    <axis xyz="0 -1 0"/>
    <limit effort="100" lower="0.0" upper="0.785398163397" velocity="100"/>
    <dynamics damping="0.5" friction="0.0"/>
  </joint>
  <link name="soft_hand_little_middle_link">
    <inertial>
      <origin xyz="0.005074337 -4.524e-06 -0.000262953"/>
      <mass value="0.05"/>
      <inertia ixx="0.00175" ixy="0.0" ixz="0.0001" iyy="0.00275" iyz="0.0" izz="0.00275"/>
    </inertial>
    <visual>
      <geometry>
        <mesh filename="package://soft_hand_description/meshes/phalanx.stl" scale=" .001 .001 .001"/>
      </geometry>
      <material name="SoftHand/DarkGrey"/>
    </visual>
    <collision>
      <geometry>
        <mesh filename="package://soft_hand_description/meshes/phalanx_collision.stl" scale=" .001 .001 .001"/>
      </geometry>
    </collision>
  </link>
  <!-- DISTAL PHALANGE -->
  <joint name="soft_hand_little_outer_joint" type="revolute">
    <origin rpy="0 0 0" xyz="0.009 0 0"/>
    <parent link="soft_hand_little_middle_link"/>
    <child link="soft_hand_little_fake_link3"/>
    <axis xyz="0 -1 0"/>
    <limit effort="100" lower="0.0" upper="0.785398163397" velocity="100"/>
    <dynamics damping="0.5" friction="0.0"/>
  </joint>
  <link name="soft_hand_little_fake_link3">
    <inertial>
      <origin xyz="0 0 0"/>
      <mass value="0.1"/>
      <inertia ixx="0.001" ixy="0.0" ixz="0.0" iyy="0.001" iyz="0.0" izz="0.001"/>
    </inertial>
  </link>
  <joint name="soft_hand_little_outer_joint_mimic" type="revolute">
    <origin rpy="0 0 0" xyz="0.013 0 0"/>
    <parent link="soft_hand_little_fake_link3"/>
    <child link="soft_hand_little_distal_link"/>
    <axis xyz="0 -1 0"/>
    <limit effort="100" lower="0.0" upper="0.785398163397" velocity="100"/>
    <dynamics damping="0.5" friction="0.0"/>
  </joint>
  <link name="soft_hand_little_distal_link">
    <inertial>
      <origin xyz="0.009849094 5.6e-07 0.000820286"/>
      <mass value="0.1"/>
      <inertia ixx="0.0035" ixy="0.0" ixz="0.0002" iyy="0.008" iyz="0.0" izz="0.0076"/>
    </inertial>
    <visual>
      <geometry>
        <mesh filename="package://soft_hand_description/meshes/fingertip.stl" scale=" .001 .001 .001"/>
      </geometry>
      <material name="SoftHand/DarkGrey"/>
    </visual>
    <collision>
      <geometry>
        <mesh filename="package://soft_hand_description/meshes/fingertip_collision.stl" scale=" .001 .001 .001"/>
      </geometry>
    </collision>
  </link>
  <!-- work in progress -->
  <transmission name="soft_hand_synergy_trans">
    <robotNamespace>soft_hand</robotNamespace>
    <type>transmission_interface/SimpleTransmission</type>
    <joint name="soft_hand_synergy_joint">
      <hardwareInterface>PositionJointInterface</hardwareInterface>
      <!--hardwareInterface>EffortJointInterface</hardwareInterface-->
    </joint>
    <actuator name="soft_hand_synergy_motor">
      <mechanicalReduction>1.0</mechanicalReduction>
    </actuator>
  </transmission>
  <transmission name="soft_hand_joint_trans">
    <robotNamespace>soft_hand</robotNamespace>
    <type>transmission_interface/AdaptiveSynergyTransmission</type>
    <joint name="soft_hand_thumb_abd_joint">
      <role>joint1</role>
      <offset>-0.0</offset>
      <mechanicalReduction>2.5</mechanicalReduction>
      <mechanicalElasticity>1.0</mechanicalElasticity>
      <!-- hardwareInterface>PositionJointInterface</hardwareInterface -->
      <hardwareInterface>EffortJointInterface</hardwareInterface>
    </joint>
    <joint name="soft_hand_thumb_inner_joint">
      <role>joint2</role>
      <offset>-0.0</offset>
      <mechanicalReduction>1.0</mechanicalReduction>
      <mechanicalElasticity>1.0</mechanicalElasticity>
      <!-- hardwareInterface>PositionJointInterface</hardwareInterface -->
      <hardwareInterface>EffortJointInterface</hardwareInterface>
    </joint>
    <joint name="soft_hand_thumb_outer_joint">
      <role>joint3</role>
      <offset>-0.0</offset>
      <mechanicalReduction>1.0</mechanicalReduction>
      <mechanicalElasticity>1.0</mechanicalElasticity>
      <!-- hardwareInterface>PositionJointInterface</hardwareInterface -->
      <hardwareInterface>EffortJointInterface</hardwareInterface>
    </joint>
    <joint name="soft_hand_index_abd_joint">
      <role>joint4</role>
      <offset>-0.0</offset>
      <mechanicalReduction>0.2</mechanicalReduction>
      <mechanicalElasticity>1.0</mechanicalElasticity>
      <!-- hardwareInterface>PositionJointInterface</hardwareInterface -->
      <hardwareInterface>EffortJointInterface</hardwareInterface>
    </joint>
    <joint name="soft_hand_index_inner_joint">
      <role>joint5</role>
      <offset>-0.0</offset>
      <mechanicalReduction>1.0</mechanicalReduction>
      <mechanicalElasticity>1.0</mechanicalElasticity>
      <!-- hardwareInterface>PositionJointInterface</hardwareInterface -->
      <hardwareInterface>EffortJointInterface</hardwareInterface>
    </joint>
    <joint name="soft_hand_index_middle_joint">
      <role>joint6</role>
      <offset>-0.0</offset>
      <mechanicalReduction>1.0</mechanicalReduction>
      <mechanicalElasticity>1.0</mechanicalElasticity>
      <!-- hardwareInterface>PositionJointInterface</hardwareInterface -->
      <hardwareInterface>EffortJointInterface</hardwareInterface>
    </joint>
    <joint name="soft_hand_index_outer_joint">
      <role>joint7</role>
      <offset>-0.0</offset>
      <mechanicalReduction>1.0</mechanicalReduction>
      <mechanicalElasticity>1.0</mechanicalElasticity>
      <!-- hardwareInterface>PositionJointInterface</hardwareInterface -->
      <hardwareInterface>EffortJointInterface</hardwareInterface>
    </joint>
    <joint name="soft_hand_middle_abd_joint">
      <role>joint8</role>
      <offset>-0.0</offset>
      <mechanicalReduction>0.001</mechanicalReduction>
      <mechanicalElasticity>1.0</mechanicalElasticity>
      <!-- hardwareInterface>PositionJointInterface</hardwareInterface -->
      <hardwareInterface>EffortJointInterface</hardwareInterface>
    </joint>
    <joint name="soft_hand_middle_inner_joint">
      <role>joint9</role>
      <offset>-0.0</offset>
      <mechanicalReduction>1.0</mechanicalReduction>
      <mechanicalElasticity>1.0</mechanicalElasticity>
      <!-- hardwareInterface>PositionJointInterface</hardwareInterface -->
      <hardwareInterface>EffortJointInterface</hardwareInterface>
    </joint>
    <joint name="soft_hand_middle_middle_joint">
      <role>joint10</role>
      <offset>-0.0</offset>
      <mechanicalReduction>1.0</mechanicalReduction>
      <mechanicalElasticity>1.0</mechanicalElasticity>
      <!-- hardwareInterface>PositionJointInterface</hardwareInterface -->
      <hardwareInterface>EffortJointInterface</hardwareInterface>
    </joint>
    <joint name="soft_hand_middle_outer_joint">
      <role>joint11</role>
      <offset>-0.0</offset>
      <mechanicalReduction>1.0</mechanicalReduction>
      <mechanicalElasticity>1.0</mechanicalElasticity>
      <!-- hardwareInterface>PositionJointInterface</hardwareInterface -->
      <hardwareInterface>EffortJointInterface</hardwareInterface>
    </joint>
    <joint name="soft_hand_ring_abd_joint">
      <role>joint12</role>
      <offset>-0.0</offset>
      <mechanicalReduction>0.2</mechanicalReduction>
      <mechanicalElasticity>1.0</mechanicalElasticity>
      <!-- hardwareInterface>PositionJointInterface</hardwareInterface -->
      <hardwareInterface>EffortJointInterface</hardwareInterface>
    </joint>
    <joint name="soft_hand_ring_inner_joint">
      <role>joint13</role>
      <offset>-0.0</offset>
      <mechanicalReduction>1.0</mechanicalReduction>
      <mechanicalElasticity>1.0</mechanicalElasticity>
      <!-- hardwareInterface>PositionJointInterface</hardwareInterface -->
      <hardwareInterface>EffortJointInterface</hardwareInterface>
    </joint>
    <joint name="soft_hand_ring_middle_joint">
      <role>joint14</role>
      <offset>-0.0</offset>
      <mechanicalReduction>1.0</mechanicalReduction>
      <mechanicalElasticity>1.0</mechanicalElasticity>
      <!-- hardwareInterface>PositionJointInterface</hardwareInterface -->
      <hardwareInterface>EffortJointInterface</hardwareInterface>
    </joint>
    <joint name="soft_hand_ring_outer_joint">
      <role>joint15</role>
      <offset>-0.0</offset>
      <mechanicalReduction>1.0</mechanicalReduction>
      <mechanicalElasticity>1.0</mechanicalElasticity>
      <!-- hardwareInterface>PositionJointInterface</hardwareInterface -->
      <hardwareInterface>EffortJointInterface</hardwareInterface>
    </joint>
    <joint name="soft_hand_little_abd_joint">
      <role>joint16</role>
      <offset>-0.0</offset>
      <mechanicalReduction>0.4</mechanicalReduction>
      <mechanicalElasticity>1.0</mechanicalElasticity>
      <!-- hardwareInterface>PositionJointInterface</hardwareInterface -->
      <hardwareInterface>EffortJointInterface</hardwareInterface>
    </joint>
    <joint name="soft_hand_little_inner_joint">
      <role>joint17</role>
      <offset>-0.0</offset>
      <mechanicalReduction>1.0</mechanicalReduction>
      <mechanicalElasticity>1.0</mechanicalElasticity>
      <!-- hardwareInterface>PositionJointInterface</hardwareInterface -->
      <hardwareInterface>EffortJointInterface</hardwareInterface>
    </joint>
    <joint name="soft_hand_little_middle_joint">
      <role>joint18</role>
      <offset>-0.0</offset>
      <mechanicalReduction>1.0</mechanicalReduction>
      <mechanicalElasticity>1.0</mechanicalElasticity>
      <!-- hardwareInterface>PositionJointInterface</hardwareInterface -->
      <hardwareInterface>EffortJointInterface</hardwareInterface>
    </joint>
    <joint name="soft_hand_little_outer_joint">
      <role>joint19</role>
      <offset>-0.0</offset>
      <mechanicalReduction>1.0</mechanicalReduction>
      <mechanicalElasticity>1.0</mechanicalElasticity>
      <!-- hardwareInterface>PositionJointInterface</hardwareInterface -->
      <hardwareInterface>EffortJointInterface</hardwareInterface>
    </joint>
    <!-- IMPORTANT: if you change the elasticity or reduction at the joints, this value must be calibrated again to
                          ensure that the joints don't go after the limits -->
    <!-- ToDO: autocalibration using the joint limits. When the synergy goes to 1, they must be at the upper limirt
                    and to 0, they must be at the lower limit -->
    <actuator name="soft_hand_actuator">
      <role>actuator1</role>
      <mechanicalReduction>4.5</mechanicalReduction>
    </actuator>
  </transmission>
  <!-- PLUGINS -->
  <!-- work in progess -->
  <gazebo>
    <plugin filename="libgazebo_ros_soft_hand.so" name="gazebo_ros_soft_hand">
      <robotNamespace>soft_hand</robotNamespace>
      <!-- select which type of hardware simulation you want:
					     - DefatulSoftHandHWSim: underactuated with adaptivity
					     - KinematicCtrlSoftHandHWSim: underactuation with pure kinematic 
					       control over joints (if you enable mimic tags, this one is automatically loaded)
					-->
    </plugin>
  </gazebo>
  <!-- LINKS -->
  <gazebo reference="soft_hand_palm_link">
    <sensor name="soft_hand_palm_link_contact" type="contact">
      <!-- the gazebo contact sensor -->
      <always_on>1</always_on>
      <update_rate>1000.0</update_rate>
      <contact>
        <collision>soft_hand_palm_link_collision</collision>
        <topic>soft_hand_palm_link_collision</topic>
      </contact>
      <!-- to publish a ros message with contact information -->
      <plugin filename="libgazebo_ros_bumper.so" name="soft_hand_palm_link_gazebo_ros_bumper_plugin">
        <alwaysOn>true</alwaysOn>
        <frameName>soft_hand_palm_link</frameName>
        <updateRate>100.0</updateRate>
        <bumperTopicName>/contacts/soft_hand_palm_link</bumperTopicName>
      </plugin>
    </sensor>
    <!--selfCollide>true</selfCollide-->
    <gravity>true</gravity>
    <mu1>1.5</mu1>
    <mu2>1.5</mu2>
    <kp>1000000.0</kp>
    <kd>30000.0</kd>
  </gazebo>
  <gazebo reference="soft_hand_thumb_knuckle_link">
    <sensor name="soft_hand_thumb_knuckle_link_contact" type="contact">
      <!-- the gazebo contact sensor -->
      <always_on>1</always_on>
      <update_rate>1000.0</update_rate>
      <contact>
        <collision>soft_hand_thumb_knuckle_link_collision</collision>
        <topic>soft_hand_thumb_knuckle_link_collision</topic>
      </contact>
      <!-- to publish a ros message with contact information -->
      <plugin filename="libgazebo_ros_bumper.so" name="soft_hand_thumb_knuckle_link_gazebo_ros_bumper_plugin">
        <alwaysOn>true</alwaysOn>
        <frameName>soft_hand_thumb_knuckle_link</frameName>
        <updateRate>100.0</updateRate>
        <bumperTopicName>/contacts/soft_hand_thumb_knuckle_link</bumperTopicName>
      </plugin>
    </sensor>
    <!--selfCollide>true</selfCollide-->
    <gravity>true</gravity>
    <mu1>1.5</mu1>
    <mu2>1.5</mu2>
    <kp>1000000.0</kp>
    <kd>30000.0</kd>
  </gazebo>
  <gazebo reference="soft_hand_thumb_proximal_link">
    <sensor name="soft_hand_thumb_proximal_link_contact" type="contact">
      <!-- the gazebo contact sensor -->
      <always_on>1</always_on>
      <update_rate>1000.0</update_rate>
      <contact>
        <collision>soft_hand_thumb_proximal_link_collision</collision>
        <topic>soft_hand_thumb_proximal_link_collision</topic>
      </contact>
      <!-- to publish a ros message with contact information -->
      <plugin filename="libgazebo_ros_bumper.so" name="soft_hand_thumb_proximal_link_gazebo_ros_bumper_plugin">
        <alwaysOn>true</alwaysOn>
        <frameName>soft_hand_thumb_proximal_link</frameName>
        <updateRate>100.0</updateRate>
        <bumperTopicName>/contacts/soft_hand_thumb_proximal_link</bumperTopicName>
      </plugin>
    </sensor>
    <!--selfCollide>true</selfCollide-->
    <gravity>true</gravity>
    <mu1>1.5</mu1>
    <mu2>1.5</mu2>
    <kp>1000000.0</kp>
    <kd>30000.0</kd>
  </gazebo>
  <gazebo reference="soft_hand_thumb_distal_link">
    <sensor name="soft_hand_thumb_distal_link_contact" type="contact">
      <!-- the gazebo contact sensor -->
      <always_on>1</always_on>
      <update_rate>1000.0</update_rate>
      <contact>
        <collision>soft_hand_thumb_distal_link_collision</collision>
        <topic>soft_hand_thumb_distal_link_collision</topic>
      </contact>
      <!-- to publish a ros message with contact information -->
      <plugin filename="libgazebo_ros_bumper.so" name="soft_hand_thumb_distal_link_gazebo_ros_bumper_plugin">
        <alwaysOn>true</alwaysOn>
        <frameName>soft_hand_thumb_distal_link</frameName>
        <updateRate>100.0</updateRate>
        <bumperTopicName>/contacts/soft_hand_thumb_distal_link</bumperTopicName>
      </plugin>
    </sensor>
    <!-- selfCollide>true</selfCollide-->
    <gravity>true</gravity>
    <mu1>1.5</mu1>
    <mu2>1.5</mu2>
    <kp>1000000.0</kp>
    <kd>30000.0</kd>
  </gazebo>
  <gazebo reference="soft_hand_index_knuckle_link">
    <sensor name="soft_hand_index_knuckle_link_contact" type="contact">
      <!-- the gazebo contact sensor -->
      <always_on>1</always_on>
      <update_rate>1000.0</update_rate>
      <contact>
        <collision>soft_hand_index_knuckle_link_collision</collision>
        <topic>soft_hand_index_knuckle_link_collision</topic>
      </contact>
      <!-- to publish a ros message with contact information -->
      <plugin filename="libgazebo_ros_bumper.so" name="soft_hand_index_knuckle_link_gazebo_ros_bumper_plugin">
        <alwaysOn>true</alwaysOn>
        <frameName>soft_hand_index_knuckle_link</frameName>
        <updateRate>100.0</updateRate>
        <bumperTopicName>/contacts/soft_hand_index_knuckle_link</bumperTopicName>
      </plugin>
    </sensor>
    <!--selfCollide>true</selfCollide-->
    <gravity>true</gravity>
    <mu1>1.5</mu1>
    <mu2>1.5</mu2>
    <kp>1000000.0</kp>
    <kd>30000.0</kd>
  </gazebo>
  <gazebo reference="soft_hand_index_proximal_link">
    <sensor name="soft_hand_index_proximal_link_contact" type="contact">
      <!-- the gazebo contact sensor -->
      <always_on>1</always_on>
      <update_rate>1000.0</update_rate>
      <contact>
        <collision>soft_hand_index_proximal_link_collision</collision>
        <topic>soft_hand_index_proximal_link_collision</topic>
      </contact>
      <!-- to publish a ros message with contact information -->
      <plugin filename="libgazebo_ros_bumper.so" name="soft_hand_index_proximal_link_gazebo_ros_bumper_plugin">
        <alwaysOn>true</alwaysOn>
        <frameName>soft_hand_index_proximal_link</frameName>
        <updateRate>100.0</updateRate>
        <bumperTopicName>/contacts/soft_hand_index_proximal_link</bumperTopicName>
      </plugin>
    </sensor>
    <!--selfCollide>true</selfCollide-->
    <gravity>true</gravity>
    <mu1>1.5</mu1>
    <mu2>1.5</mu2>
    <kp>1000000.0</kp>
    <kd>30000.0</kd>
  </gazebo>
  <gazebo reference="soft_hand_index_middle_link">
    <sensor name="soft_hand_index_middle_link_contact" type="contact">
      <!-- the gazebo contact sensor -->
      <always_on>1</always_on>
      <update_rate>1000.0</update_rate>
      <contact>
        <collision>soft_hand_index_middle_link_collision</collision>
        <topic>soft_hand_index_middle_link_collision</topic>
      </contact>
      <!-- to publish a ros message with contact information -->
      <plugin filename="libgazebo_ros_bumper.so" name="soft_hand_index_middle_link_gazebo_ros_bumper_plugin">
        <alwaysOn>true</alwaysOn>
        <frameName>soft_hand_index_middle_link</frameName>
        <updateRate>100.0</updateRate>
        <bumperTopicName>/contacts/soft_hand_index_middle_link</bumperTopicName>
      </plugin>
    </sensor>
    <!--selfCollide>true</selfCollide-->
    <gravity>true</gravity>
    <mu1>1.5</mu1>
    <mu2>1.5</mu2>
    <kp>1000000.0</kp>
    <kd>30000.0</kd>
  </gazebo>
  <gazebo reference="soft_hand_index_distal_link">
    <sensor name="soft_hand_index_distal_link_contact" type="contact">
      <!-- the gazebo contact sensor -->
      <always_on>1</always_on>
      <update_rate>1000.0</update_rate>
      <contact>
        <collision>soft_hand_index_distal_link_collision</collision>
        <topic>soft_hand_index_distal_link_collision</topic>
      </contact>
      <!-- to publish a ros message with contact information -->
      <plugin filename="libgazebo_ros_bumper.so" name="soft_hand_index_distal_link_gazebo_ros_bumper_plugin">
        <alwaysOn>true</alwaysOn>
        <frameName>soft_hand_index_distal_link</frameName>
        <updateRate>100.0</updateRate>
        <bumperTopicName>/contacts/soft_hand_index_distal_link</bumperTopicName>
      </plugin>
    </sensor>
    <!-- selfCollide>true</selfCollide-->
    <gravity>true</gravity>
    <mu1>1.5</mu1>
    <mu2>1.5</mu2>
    <kp>1000000.0</kp>
    <kd>30000.0</kd>
  </gazebo>
  <gazebo reference="soft_hand_middle_knuckle_link">
    <sensor name="soft_hand_middle_knuckle_link_contact" type="contact">
      <!-- the gazebo contact sensor -->
      <always_on>1</always_on>
      <update_rate>1000.0</update_rate>
      <contact>
        <collision>soft_hand_middle_knuckle_link_collision</collision>
        <topic>soft_hand_middle_knuckle_link_collision</topic>
      </contact>
      <!-- to publish a ros message with contact information -->
      <plugin filename="libgazebo_ros_bumper.so" name="soft_hand_middle_knuckle_link_gazebo_ros_bumper_plugin">
        <alwaysOn>true</alwaysOn>
        <frameName>soft_hand_middle_knuckle_link</frameName>
        <updateRate>100.0</updateRate>
        <bumperTopicName>/contacts/soft_hand_middle_knuckle_link</bumperTopicName>
      </plugin>
    </sensor>
    <!--selfCollide>true</selfCollide-->
    <gravity>true</gravity>
    <mu1>1.5</mu1>
    <mu2>1.5</mu2>
    <kp>1000000.0</kp>
    <kd>30000.0</kd>
  </gazebo>
  <gazebo reference="soft_hand_middle_proximal_link">
    <sensor name="soft_hand_middle_proximal_link_contact" type="contact">
      <!-- the gazebo contact sensor -->
      <always_on>1</always_on>
      <update_rate>1000.0</update_rate>
      <contact>
        <collision>soft_hand_middle_proximal_link_collision</collision>
        <topic>soft_hand_middle_proximal_link_collision</topic>
      </contact>
      <!-- to publish a ros message with contact information -->
      <plugin filename="libgazebo_ros_bumper.so" name="soft_hand_middle_proximal_link_gazebo_ros_bumper_plugin">
        <alwaysOn>true</alwaysOn>
        <frameName>soft_hand_middle_proximal_link</frameName>
        <updateRate>100.0</updateRate>
        <bumperTopicName>/contacts/soft_hand_middle_proximal_link</bumperTopicName>
      </plugin>
    </sensor>
    <!--selfCollide>true</selfCollide-->
    <gravity>true</gravity>
    <mu1>1.5</mu1>
    <mu2>1.5</mu2>
    <kp>1000000.0</kp>
    <kd>30000.0</kd>
  </gazebo>
  <gazebo reference="soft_hand_middle_middle_link">
    <sensor name="soft_hand_middle_middle_link_contact" type="contact">
      <!-- the gazebo contact sensor -->
      <always_on>1</always_on>
      <update_rate>1000.0</update_rate>
      <contact>
        <collision>soft_hand_middle_middle_link_collision</collision>
        <topic>soft_hand_middle_middle_link_collision</topic>
      </contact>
      <!-- to publish a ros message with contact information -->
      <plugin filename="libgazebo_ros_bumper.so" name="soft_hand_middle_middle_link_gazebo_ros_bumper_plugin">
        <alwaysOn>true</alwaysOn>
        <frameName>soft_hand_middle_middle_link</frameName>
        <updateRate>100.0</updateRate>
        <bumperTopicName>/contacts/soft_hand_middle_middle_link</bumperTopicName>
      </plugin>
    </sensor>
    <!--selfCollide>true</selfCollide-->
    <gravity>true</gravity>
    <mu1>1.5</mu1>
    <mu2>1.5</mu2>
    <kp>1000000.0</kp>
    <kd>30000.0</kd>
  </gazebo>
  <gazebo reference="soft_hand_middle_distal_link">
    <sensor name="soft_hand_middle_distal_link_contact" type="contact">
      <!-- the gazebo contact sensor -->
      <always_on>1</always_on>
      <update_rate>1000.0</update_rate>
      <contact>
        <collision>soft_hand_middle_distal_link_collision</collision>
        <topic>soft_hand_middle_distal_link_collision</topic>
      </contact>
      <!-- to publish a ros message with contact information -->
      <plugin filename="libgazebo_ros_bumper.so" name="soft_hand_middle_distal_link_gazebo_ros_bumper_plugin">
        <alwaysOn>true</alwaysOn>
        <frameName>soft_hand_middle_distal_link</frameName>
        <updateRate>100.0</updateRate>
        <bumperTopicName>/contacts/soft_hand_middle_distal_link</bumperTopicName>
      </plugin>
    </sensor>
    <!-- selfCollide>true</selfCollide-->
    <gravity>true</gravity>
    <mu1>1.5</mu1>
    <mu2>1.5</mu2>
    <kp>1000000.0</kp>
    <kd>30000.0</kd>
  </gazebo>
  <gazebo reference="soft_hand_ring_knuckle_link">
    <sensor name="soft_hand_ring_knuckle_link_contact" type="contact">
      <!-- the gazebo contact sensor -->
      <always_on>1</always_on>
      <update_rate>1000.0</update_rate>
      <contact>
        <collision>soft_hand_ring_knuckle_link_collision</collision>
        <topic>soft_hand_ring_knuckle_link_collision</topic>
      </contact>
      <!-- to publish a ros message with contact information -->
      <plugin filename="libgazebo_ros_bumper.so" name="soft_hand_ring_knuckle_link_gazebo_ros_bumper_plugin">
        <alwaysOn>true</alwaysOn>
        <frameName>soft_hand_ring_knuckle_link</frameName>
        <updateRate>100.0</updateRate>
        <bumperTopicName>/contacts/soft_hand_ring_knuckle_link</bumperTopicName>
      </plugin>
    </sensor>
    <!--selfCollide>true</selfCollide-->
    <gravity>true</gravity>
    <mu1>1.5</mu1>
    <mu2>1.5</mu2>
    <kp>1000000.0</kp>
    <kd>30000.0</kd>
  </gazebo>
  <gazebo reference="soft_hand_ring_proximal_link">
    <sensor name="soft_hand_ring_proximal_link_contact" type="contact">
      <!-- the gazebo contact sensor -->
      <always_on>1</always_on>
      <update_rate>1000.0</update_rate>
      <contact>
        <collision>soft_hand_ring_proximal_link_collision</collision>
        <topic>soft_hand_ring_proximal_link_collision</topic>
      </contact>
      <!-- to publish a ros message with contact information -->
      <plugin filename="libgazebo_ros_bumper.so" name="soft_hand_ring_proximal_link_gazebo_ros_bumper_plugin">
        <alwaysOn>true</alwaysOn>
        <frameName>soft_hand_ring_proximal_link</frameName>
        <updateRate>100.0</updateRate>
        <bumperTopicName>/contacts/soft_hand_ring_proximal_link</bumperTopicName>
      </plugin>
    </sensor>
    <!--selfCollide>true</selfCollide-->
    <gravity>true</gravity>
    <mu1>1.5</mu1>
    <mu2>1.5</mu2>
    <kp>1000000.0</kp>
    <kd>30000.0</kd>
  </gazebo>
  <gazebo reference="soft_hand_ring_middle_link">
    <sensor name="soft_hand_ring_middle_link_contact" type="contact">
      <!-- the gazebo contact sensor -->
      <always_on>1</always_on>
      <update_rate>1000.0</update_rate>
      <contact>
        <collision>soft_hand_ring_middle_link_collision</collision>
        <topic>soft_hand_ring_middle_link_collision</topic>
      </contact>
      <!-- to publish a ros message with contact information -->
      <plugin filename="libgazebo_ros_bumper.so" name="soft_hand_ring_middle_link_gazebo_ros_bumper_plugin">
        <alwaysOn>true</alwaysOn>
        <frameName>soft_hand_ring_middle_link</frameName>
        <updateRate>100.0</updateRate>
        <bumperTopicName>/contacts/soft_hand_ring_middle_link</bumperTopicName>
      </plugin>
    </sensor>
    <!--selfCollide>true</selfCollide-->
    <gravity>true</gravity>
    <mu1>1.5</mu1>
    <mu2>1.5</mu2>
    <kp>1000000.0</kp>
    <kd>30000.0</kd>
  </gazebo>
  <gazebo reference="soft_hand_ring_distal_link">
    <sensor name="soft_hand_ring_distal_link_contact" type="contact">
      <!-- the gazebo contact sensor -->
      <always_on>1</always_on>
      <update_rate>1000.0</update_rate>
      <contact>
        <collision>soft_hand_ring_distal_link_collision</collision>
        <topic>soft_hand_ring_distal_link_collision</topic>
      </contact>
      <!-- to publish a ros message with contact information -->
      <plugin filename="libgazebo_ros_bumper.so" name="soft_hand_ring_distal_link_gazebo_ros_bumper_plugin">
        <alwaysOn>true</alwaysOn>
        <frameName>soft_hand_ring_distal_link</frameName>
        <updateRate>100.0</updateRate>
        <bumperTopicName>/contacts/soft_hand_ring_distal_link</bumperTopicName>
      </plugin>
    </sensor>
    <!-- selfCollide>true</selfCollide-->
    <gravity>true</gravity>
    <mu1>1.5</mu1>
    <mu2>1.5</mu2>
    <kp>1000000.0</kp>
    <kd>30000.0</kd>
  </gazebo>
  <gazebo reference="soft_hand_little_knuckle_link">
    <sensor name="soft_hand_little_knuckle_link_contact" type="contact">
      <!-- the gazebo contact sensor -->
      <always_on>1</always_on>
      <update_rate>1000.0</update_rate>
      <contact>
        <collision>soft_hand_little_knuckle_link_collision</collision>
        <topic>soft_hand_little_knuckle_link_collision</topic>
      </contact>
      <!-- to publish a ros message with contact information -->
      <plugin filename="libgazebo_ros_bumper.so" name="soft_hand_little_knuckle_link_gazebo_ros_bumper_plugin">
        <alwaysOn>true</alwaysOn>
        <frameName>soft_hand_little_knuckle_link</frameName>
        <updateRate>100.0</updateRate>
        <bumperTopicName>/contacts/soft_hand_little_knuckle_link</bumperTopicName>
      </plugin>
    </sensor>
    <!--selfCollide>true</selfCollide-->
    <gravity>true</gravity>
    <mu1>1.5</mu1>
    <mu2>1.5</mu2>
    <kp>1000000.0</kp>
    <kd>30000.0</kd>
  </gazebo>
  <gazebo reference="soft_hand_little_proximal_link">
    <sensor name="soft_hand_little_proximal_link_contact" type="contact">
      <!-- the gazebo contact sensor -->
      <always_on>1</always_on>
      <update_rate>1000.0</update_rate>
      <contact>
        <collision>soft_hand_little_proximal_link_collision</collision>
        <topic>soft_hand_little_proximal_link_collision</topic>
      </contact>
      <!-- to publish a ros message with contact information -->
      <plugin filename="libgazebo_ros_bumper.so" name="soft_hand_little_proximal_link_gazebo_ros_bumper_plugin">
        <alwaysOn>true</alwaysOn>
        <frameName>soft_hand_little_proximal_link</frameName>
        <updateRate>100.0</updateRate>
        <bumperTopicName>/contacts/soft_hand_little_proximal_link</bumperTopicName>
      </plugin>
    </sensor>
    <!--selfCollide>true</selfCollide-->
    <gravity>true</gravity>
    <mu1>1.5</mu1>
    <mu2>1.5</mu2>
    <kp>1000000.0</kp>
    <kd>30000.0</kd>
  </gazebo>
  <gazebo reference="soft_hand_little_middle_link">
    <sensor name="soft_hand_little_middle_link_contact" type="contact">
      <!-- the gazebo contact sensor -->
      <always_on>1</always_on>
      <update_rate>1000.0</update_rate>
      <contact>
        <collision>soft_hand_little_middle_link_collision</collision>
        <topic>soft_hand_little_middle_link_collision</topic>
      </contact>
      <!-- to publish a ros message with contact information -->
      <plugin filename="libgazebo_ros_bumper.so" name="soft_hand_little_middle_link_gazebo_ros_bumper_plugin">
        <alwaysOn>true</alwaysOn>
        <frameName>soft_hand_little_middle_link</frameName>
        <updateRate>100.0</updateRate>
        <bumperTopicName>/contacts/soft_hand_little_middle_link</bumperTopicName>
      </plugin>
    </sensor>
    <!--selfCollide>true</selfCollide-->
    <gravity>true</gravity>
    <mu1>1.5</mu1>
    <mu2>1.5</mu2>
    <kp>1000000.0</kp>
    <kd>30000.0</kd>
  </gazebo>
  <gazebo reference="soft_hand_little_distal_link">
    <sensor name="soft_hand_little_distal_link_contact" type="contact">
      <!-- the gazebo contact sensor -->
      <always_on>1</always_on>
      <update_rate>1000.0</update_rate>
      <contact>
        <collision>soft_hand_little_distal_link_collision</collision>
        <topic>soft_hand_little_distal_link_collision</topic>
      </contact>
      <!-- to publish a ros message with contact information -->
      <plugin filename="libgazebo_ros_bumper.so" name="soft_hand_little_distal_link_gazebo_ros_bumper_plugin">
        <alwaysOn>true</alwaysOn>
        <frameName>soft_hand_little_distal_link</frameName>
        <updateRate>100.0</updateRate>
        <bumperTopicName>/contacts/soft_hand_little_distal_link</bumperTopicName>
      </plugin>
    </sensor>
    <!-- selfCollide>true</selfCollide-->
    <gravity>true</gravity>
    <mu1>1.5</mu1>
    <mu2>1.5</mu2>
    <kp>1000000.0</kp>
    <kd>30000.0</kd>
  </gazebo>
  <!-- JOINTS -->
  <gazebo reference="soft_hand_thumb_abd_joint">
    <provideFeedback>True</provideFeedback>
    <!--
		<kp> </kp>
		<kd> 1.0 </kd>
		<stopCfm> </stopCfm>
		<stopErp> </stopErp>
		<cfmDamping> </cfmDamping>
		<fudgeFactor> </fudgeFactor>
		-->
  </gazebo>
  <gazebo reference="soft_hand_thumb_inner_joint">
    <provideFeedback>True</provideFeedback>
    <!--
		<kp> </kp>
		<kd> 1.0 </kd>
		<stopCfm> </stopCfm>
		<stopErp> </stopErp>
		<cfmDamping> </cfmDamping>
		<fudgeFactor> </fudgeFactor>
		-->
  </gazebo>
  <gazebo reference="soft_hand_thumb_outer_joint">
    <provideFeedback>True</provideFeedback>
    <!--
		<kp> </kp>
		<kd> 1.0 </kd>
		<stopCfm> </stopCfm>
		<stopErp> </stopErp>
		<cfmDamping> </cfmDamping>
		<fudgeFactor> </fudgeFactor>
		-->
  </gazebo>
  <gazebo reference="soft_hand_index_abd_joint">
    <provideFeedback>True</provideFeedback>
    <!--
		<kp> </kp>
		<kd> 1.0 </kd>
		<stopCfm> </stopCfm>
		<stopErp> </stopErp>
		<cfmDamping> </cfmDamping>
		<fudgeFactor> </fudgeFactor>
		-->
  </gazebo>
  <gazebo reference="soft_hand_index_inner_joint">
    <provideFeedback>True</provideFeedback>
    <!--
		<kp> </kp>
		<kd> 1.0 </kd>
		<stopCfm> </stopCfm>
		<stopErp> </stopErp>
		<cfmDamping> </cfmDamping>
		<fudgeFactor> </fudgeFactor>
		-->
  </gazebo>
  <gazebo reference="soft_hand_index_middle_joint">
    <provideFeedback>True</provideFeedback>
    <!--
		<kp> </kp>
		<kd> 1.0 </kd>
		<stopCfm> </stopCfm>
		<stopErp> </stopErp>
		<cfmDamping> </cfmDamping>
		<fudgeFactor> </fudgeFactor>
		-->
  </gazebo>
  <gazebo reference="soft_hand_index_outer_joint">
    <provideFeedback>True</provideFeedback>
    <!--
		<kp> </kp>
		<kd> 1.0 </kd>
		<stopCfm> </stopCfm>
		<stopErp> </stopErp>
		<cfmDamping> </cfmDamping>
		<fudgeFactor> </fudgeFactor>
		-->
  </gazebo>
  <gazebo reference="soft_hand_middle_abd_joint">
    <provideFeedback>True</provideFeedback>
    <!--
		<kp> </kp>
		<kd> 1.0 </kd>
		<stopCfm> </stopCfm>
		<stopErp> </stopErp>
		<cfmDamping> </cfmDamping>
		<fudgeFactor> </fudgeFactor>
		-->
  </gazebo>
  <gazebo reference="soft_hand_middle_inner_joint">
    <provideFeedback>True</provideFeedback>
    <!--
		<kp> </kp>
		<kd> 1.0 </kd>
		<stopCfm> </stopCfm>
		<stopErp> </stopErp>
		<cfmDamping> </cfmDamping>
		<fudgeFactor> </fudgeFactor>
		-->
  </gazebo>
  <gazebo reference="soft_hand_middle_middle_joint">
    <provideFeedback>True</provideFeedback>
    <!--
		<kp> </kp>
		<kd> 1.0 </kd>
		<stopCfm> </stopCfm>
		<stopErp> </stopErp>
		<cfmDamping> </cfmDamping>
		<fudgeFactor> </fudgeFactor>
		-->
  </gazebo>
  <gazebo reference="soft_hand_middle_outer_joint">
    <provideFeedback>True</provideFeedback>
    <!--
		<kp> </kp>
		<kd> 1.0 </kd>
		<stopCfm> </stopCfm>
		<stopErp> </stopErp>
		<cfmDamping> </cfmDamping>
		<fudgeFactor> </fudgeFactor>
		-->
  </gazebo>
  <gazebo reference="soft_hand_ring_abd_joint">
    <provideFeedback>True</provideFeedback>
    <!--
		<kp> </kp>
		<kd> 1.0 </kd>
		<stopCfm> </stopCfm>
		<stopErp> </stopErp>
		<cfmDamping> </cfmDamping>
		<fudgeFactor> </fudgeFactor>
		-->
  </gazebo>
  <gazebo reference="soft_hand_ring_inner_joint">
    <provideFeedback>True</provideFeedback>
    <!--
		<kp> </kp>
		<kd> 1.0 </kd>
		<stopCfm> </stopCfm>
		<stopErp> </stopErp>
		<cfmDamping> </cfmDamping>
		<fudgeFactor> </fudgeFactor>
		-->
  </gazebo>
  <gazebo reference="soft_hand_ring_middle_joint">
    <provideFeedback>True</provideFeedback>
    <!--
		<kp> </kp>
		<kd> 1.0 </kd>
		<stopCfm> </stopCfm>
		<stopErp> </stopErp>
		<cfmDamping> </cfmDamping>
		<fudgeFactor> </fudgeFactor>
		-->
  </gazebo>
  <gazebo reference="soft_hand_ring_outer_joint">
    <provideFeedback>True</provideFeedback>
    <!--
		<kp> </kp>
		<kd> 1.0 </kd>
		<stopCfm> </stopCfm>
		<stopErp> </stopErp>
		<cfmDamping> </cfmDamping>
		<fudgeFactor> </fudgeFactor>
		-->
  </gazebo>
  <gazebo reference="soft_hand_little_abd_joint">
    <provideFeedback>True</provideFeedback>
    <!--
		<kp> </kp>
		<kd> 1.0 </kd>
		<stopCfm> </stopCfm>
		<stopErp> </stopErp>
		<cfmDamping> </cfmDamping>
		<fudgeFactor> </fudgeFactor>
		-->
  </gazebo>
  <gazebo reference="soft_hand_little_inner_joint">
    <provideFeedback>True</provideFeedback>
    <!--
		<kp> </kp>
		<kd> 1.0 </kd>
		<stopCfm> </stopCfm>
		<stopErp> </stopErp>
		<cfmDamping> </cfmDamping>
		<fudgeFactor> </fudgeFactor>
		-->
  </gazebo>
  <gazebo reference="soft_hand_little_middle_joint">
    <provideFeedback>True</provideFeedback>
    <!--
		<kp> </kp>
		<kd> 1.0 </kd>
		<stopCfm> </stopCfm>
		<stopErp> </stopErp>
		<cfmDamping> </cfmDamping>
		<fudgeFactor> </fudgeFactor>
		-->
  </gazebo>
  <gazebo reference="soft_hand_little_outer_joint">
    <provideFeedback>True</provideFeedback>
    <!--
		<kp> </kp>
		<kd> 1.0 </kd>
		<stopCfm> </stopCfm>
		<stopErp> </stopErp>
		<cfmDamping> </cfmDamping>
		<fudgeFactor> </fudgeFactor>
		-->
  </gazebo>
  <!-- mimic joints -->
  <gazebo reference="soft_hand_thumb_inner_joint_mimic">
    <provideFeedback>True</provideFeedback>
    <!--
		<kp> </kp>
		<kd> 1.0 </kd>
		<stopCfm> </stopCfm>
		<stopErp> </stopErp>
		<cfmDamping> </cfmDamping>
		<fudgeFactor> </fudgeFactor>
		-->
  </gazebo>
  <gazebo reference="soft_hand_thumb_outer_joint_mimic">
    <provideFeedback>True</provideFeedback>
    <!--
		<kp> </kp>
		<kd> 1.0 </kd>
		<stopCfm> </stopCfm>
		<stopErp> </stopErp>
		<cfmDamping> </cfmDamping>
		<fudgeFactor> </fudgeFactor>
		-->
  </gazebo>
  <gazebo reference="soft_hand_index_inner_joint_mimic">
    <provideFeedback>True</provideFeedback>
    <!--
		<kp> </kp>
		<kd> 1.0 </kd>
		<stopCfm> </stopCfm>
		<stopErp> </stopErp>
		<cfmDamping> </cfmDamping>
		<fudgeFactor> </fudgeFactor>
		-->
  </gazebo>
  <gazebo reference="soft_hand_index_middle_joint_mimic">
    <provideFeedback>True</provideFeedback>
    <!--
		<kp> </kp>
		<kd> 1.0 </kd>
		<stopCfm> </stopCfm>
		<stopErp> </stopErp>
		<cfmDamping> </cfmDamping>
		<fudgeFactor> </fudgeFactor>
		-->
  </gazebo>
  <gazebo reference="soft_hand_index_outer_joint_mimic">
    <provideFeedback>True</provideFeedback>
    <!--
		<kp> </kp>
		<kd> 1.0 </kd>
		<stopCfm> </stopCfm>
		<stopErp> </stopErp>
		<cfmDamping> </cfmDamping>
		<fudgeFactor> </fudgeFactor>
		-->
  </gazebo>
  <gazebo reference="soft_hand_middle_inner_joint_mimic">
    <provideFeedback>True</provideFeedback>
    <!--
		<kp> </kp>
		<kd> 1.0 </kd>
		<stopCfm> </stopCfm>
		<stopErp> </stopErp>
		<cfmDamping> </cfmDamping>
		<fudgeFactor> </fudgeFactor>
		-->
  </gazebo>
  <gazebo reference="soft_hand_middle_middle_joint_mimic">
    <provideFeedback>True</provideFeedback>
    <!--
		<kp> </kp>
		<kd> 1.0 </kd>
		<stopCfm> </stopCfm>
		<stopErp> </stopErp>
		<cfmDamping> </cfmDamping>
		<fudgeFactor> </fudgeFactor>
		-->
  </gazebo>
  <gazebo reference="soft_hand_middle_outer_joint_mimic">
    <provideFeedback>True</provideFeedback>
    <!--
		<kp> </kp>
		<kd> 1.0 </kd>
		<stopCfm> </stopCfm>
		<stopErp> </stopErp>
		<cfmDamping> </cfmDamping>
		<fudgeFactor> </fudgeFactor>
		-->
  </gazebo>
  <gazebo reference="soft_hand_ring_inner_joint_mimic">
    <provideFeedback>True</provideFeedback>
    <!--
		<kp> </kp>
		<kd> 1.0 </kd>
		<stopCfm> </stopCfm>
		<stopErp> </stopErp>
		<cfmDamping> </cfmDamping>
		<fudgeFactor> </fudgeFactor>
		-->
  </gazebo>
  <gazebo reference="soft_hand_ring_middle_joint_mimic">
    <provideFeedback>True</provideFeedback>
    <!--
		<kp> </kp>
		<kd> 1.0 </kd>
		<stopCfm> </stopCfm>
		<stopErp> </stopErp>
		<cfmDamping> </cfmDamping>
		<fudgeFactor> </fudgeFactor>
		-->
  </gazebo>
  <gazebo reference="soft_hand_ring_outer_joint_mimic">
    <provideFeedback>True</provideFeedback>
    <!--
		<kp> </kp>
		<kd> 1.0 </kd>
		<stopCfm> </stopCfm>
		<stopErp> </stopErp>
		<cfmDamping> </cfmDamping>
		<fudgeFactor> </fudgeFactor>
		-->
  </gazebo>
  <gazebo reference="soft_hand_little_inner_joint_mimic">
    <provideFeedback>True</provideFeedback>
    <!--
		<kp> </kp>
		<kd> 1.0 </kd>
		<stopCfm> </stopCfm>
		<stopErp> </stopErp>
		<cfmDamping> </cfmDamping>
		<fudgeFactor> </fudgeFactor>
		-->
  </gazebo>
  <gazebo reference="soft_hand_little_middle_joint_mimic">
    <provideFeedback>True</provideFeedback>
    <!--
		<kp> </kp>
		<kd> 1.0 </kd>
		<stopCfm> </stopCfm>
		<stopErp> </stopErp>
		<cfmDamping> </cfmDamping>
		<fudgeFactor> </fudgeFactor>
		-->
  </gazebo>
  <gazebo reference="soft_hand_little_outer_joint_mimic">
    <provideFeedback>True</provideFeedback>
    <!--
		<kp> </kp>
		<kd> 1.0 </kd>
		<stopCfm> </stopCfm>
		<stopErp> </stopErp>
		<cfmDamping> </cfmDamping>
		<fudgeFactor> </fudgeFactor>
		-->
  </gazebo>

   <klampt package_root="." fixed_root_link="1" sensors="soft_hand_sensors.xml">
   <!--klampt package_root="." use_vis_geom="1" fixed_root_link="1"/-->
     <link name="world" physical="0" />
     <link name="soft_hand_invisible_wire_link" physical="false" servoP="3.0" servoD="0.3" servoI="0.03"/>
     <link name="soft_hand_thumb_fake_link1" servoP="3.0" servoD="0.3" servoI="0.0"/>
     <link name="soft_hand_thumb_fake_link3" servoP="3.0" servoD="0.3" servoI="0.0"/>
     <link name="soft_hand_index_fake_link1" servoP="3.0" servoD="0.3" servoI="0.0"/>
     <link name="soft_hand_index_fake_link2" servoP="3.0" servoD="0.3" servoI="0.0"/>
     <link name="soft_hand_index_fake_link3" servoP="3.0" servoD="0.3" servoI="0.0"/>
     <link name="soft_hand_middle_fake_link1" servoP="3.0" servoD="0.3" servoI="0.0"/>
     <link name="soft_hand_middle_fake_link2" servoP="3.0" servoD="0.3" servoI="0.0"/>
     <link name="soft_hand_middle_fake_link3" servoP="3.0" servoD="0.3" servoI="0.0"/>
     <link name="soft_hand_ring_fake_link1" servoP="3.0" servoD="0.3" servoI="0.0"/>
     <link name="soft_hand_ring_fake_link2" servoP="3.0" servoD="0.3" servoI="0.0"/>
     <link name="soft_hand_ring_fake_link3" servoP="3.0" servoD="0.3" servoI="0.0"/>
     <link name="soft_hand_little_fake_link1" servoP="3.0" servoD="0.3" servoI="0.0"/>
     <link name="soft_hand_little_fake_link2" servoP="3.0" servoD="0.3" servoI="0.0"/>
     <link name="soft_hand_little_fake_link3" servoP="3.0" servoD="0.3" servoI="0.0"/>
   </klampt>
</robot>


